Workbook

Sheet Atlas
B2: The Decomposition Atlas — wave-66
B4: field | C4: value
B5: What this is | C5: Every sibling work pushed to SuperInstance (and the external research it leaned on), decomposed into elementary parts as spreadsheet logic.
B6: Method | C6: 5 canonical layers (substrate/mechanism/policy/interface/evidence); each part carries a gate, a failure mode, and file:line evidence; jevs swept the gates (soft emits; observation only at holes).
B7: Corpus | C7: 29 works across 6 families (substrate, garden, swarm, organ, labs, meta)
B8: Elementary parts | C8: 528
B9: Gated parts | C9: 401 (75.9%)
B10: Gate holes (observed) | C10: 127
B11: Gate kinds | C11: invariant:100, postcondition:87, admission:67, seal:52, precondition:50, budget:25, conservation:20
B12: Sweep field | C12: exoj policy=ledger, deformations=474, observations=130, prob_open=0.14
B13: Chain of record | C13: 606 links, verify ok=True, tip 13463fd02be3ac4f…
B14: Doctrine | C14: Elementary = cannot be split further without changing meaning. Decision rules before the run. Honest negatives are crown jewels. Ledgers append-only.
B17: The five layers of logic
B18: 0 | C18: substrate | D18: what irreducible representation does the work stand on?
B19: 1 | C19: mechanism | D19: what transforms state, and from what to what?
B20: 2 | C20: policy | D20: what decides, admits, prices, or refuses?
B21: 3 | C21: interface | D21: what does the outside touch (wires, tools, sheets)?
B22: 4 | C22: evidence | D22: what proves it ran, and what makes tampering loud?

Sheet Corpus
B2: Corpus — the studied works
B4: work | C4: family | D4: repo_path | E4: head | F4: smoke_verdict | G4: smoke_notes | H4: essence | I4: parts | J4: gates | K4: holes | L4: L0 | M4: L1 | N4: L2 | O4: L3 | P4: L4 | Q4: ideas | R4: prob_open
B5: qthe | C5: substrate | D5: /home/z/my-project/qthe | E5: 6017f80 | F5: PASS 54/54 | G5: Repo's own negative-control selftest: 54 cases, 0 escapes (S1 tamper sweep 49/49, S2-S6 fail-closed). Cheapest runnable in-repo suite. Honest negatives: (1) the | H5: One-byte ternary hyper-embedding: 6-bit spatial amplitude + 2-bit timbre, integer-exact kernel with wormhole mechanics and pre-registered gates. | I5: =COUNTIF(Parts!B5:B532,B5) -> 22 | J5: =COUNTIFS(Parts!B5:B532,B5,Parts!K5:K532,"<>") -> 21 | K5: =I5-J5 -> 1 | L5: =COUNTIFS(Parts!B5:B532,B5,Parts!E5:E532,0) -> 4 | M5: =COUNTIFS(Parts!B5:B532,B5,Parts!E5:E532,1) -> 9 | N5: =COUNTIFS(Parts!B5:B532,B5,Parts!E5:E532,2) -> 3 | O5: =COUNTIFS(Parts!B5:B532,B5,Parts!E5:E532,3) -> 2 | P5: =COUNTIFS(Parts!B5:B532,B5,Parts!E5:E532,4) -> 4 | R5: 0.1226
B6: quilt-jepa | C6: substrate | D6: /home/z/my-project/quilt-jepa | E6: a47762a | F6: PASS (chain + seals) | G6: Repo's own fail-closed verifier, read-only: 'OK chain 7 rows, tip 09e84771c690..., claims 3/6, registration seal verified' exit 0. Honest negatives: (1) `node r | H6: Tiny JEPA world model in a cell mesh: per-cell latents, EMA targets, conservation-law surprise diffusion, ten rounds of pre-registered claims. | I6: =COUNTIF(Parts!B5:B532,B6) -> 18 | J6: =COUNTIFS(Parts!B5:B532,B6,Parts!K5:K532,"<>") -> 15 | K6: =I6-J6 -> 3 | L6: =COUNTIFS(Parts!B5:B532,B6,Parts!E5:E532,0) -> 4 | M6: =COUNTIFS(Parts!B5:B532,B6,Parts!E5:E532,1) -> 7 | N6: =COUNTIFS(Parts!B5:B532,B6,Parts!E5:E532,2) -> 2 | O6: =COUNTIFS(Parts!B5:B532,B6,Parts!E5:E532,3) -> 1 | P6: =COUNTIFS(Parts!B5:B532,B6,Parts!E5:E532,4) -> 4 | R6: 0.1308
B7: jev-quilt | C7: substrate | D7: /home/z/my-project/jev-quilt | E7: 30e431b | F7: PASS 249 ran, 0 failures (6 skipped, 2 expected failures) in 38.5s | G7: Full suite measured live (README's '81 passed, 3 skipped' is stale — the suite has grown; suite status is MEASURED not written, exactly as the README demands). | H7: Cellular-first decision substrate: typed decision-surface cells, delta hooks with deadband floors, per-cell append-only bookkeeper, exact Q16 rationals. | I7: =COUNTIF(Parts!B5:B532,B7) -> 20 | J7: =COUNTIFS(Parts!B5:B532,B7,Parts!K5:K532,"<>") -> 18 | K7: =I7-J7 -> 2 | L7: =COUNTIFS(Parts!B5:B532,B7,Parts!E5:E532,0) -> 4 | M7: =COUNTIFS(Parts!B5:B532,B7,Parts!E5:E532,1) -> 4 | N7: =COUNTIFS(Parts!B5:B532,B7,Parts!E5:E532,2) -> 7 | O7: =COUNTIFS(Parts!B5:B532,B7,Parts!E5:E532,3) -> 2 | P7: =COUNTIFS(Parts!B5:B532,B7,Parts!E5:E532,4) -> 3 | R7: 0.1132
B8: quilt-qcells | C8: substrate | D8: /home/z/my-project/quilt-qcells | E8: 615ddcf | F8: PASS — ALL GREEN, P1-P4 (16 circuits, 1418 rows, 4254/4254 tamper localized, 5/5 negatives, 6.4s) | G8: Run in a /tmp scratch copy (cp -rp) because the task forbids modifying the studied repo and a conformance run writes receipts. Honest negative found: the commit | H8: Quantum ops as quilt cells: the fnv1a-64 hash-chain ledger IS the circuit — 7 opcodes, replay equals oracle, single-byte tamper localization, out-of-band anchors. | I8: =COUNTIF(Parts!B5:B532,B8) -> 21 | J8: =COUNTIFS(Parts!B5:B532,B8,Parts!K5:K532,"<>") -> 20 | K8: =I8-J8 -> 1 | L8: =COUNTIFS(Parts!B5:B532,B8,Parts!E5:E532,0) -> 4 | M8: =COUNTIFS(Parts!B5:B532,B8,Parts!E5:E532,1) -> 4 | N8: =COUNTIFS(Parts!B5:B532,B8,Parts!E5:E532,2) -> 4 | O8: =COUNTIFS(Parts!B5:B532,B8,Parts!E5:E532,3) -> 3 | P8: =COUNTIFS(Parts!B5:B532,B8,Parts!E5:E532,4) -> 6 | R8: 0.137
B9: jev-garden | C9: garden | D9: /home/z/my-project/jev-garden | E9: d05e1d9 | F9: PASS 30/30 | G9: Second verdict: node smoke.mjs -> PASS 9/9 (exit 0). Both offline, no API key, <5s. teacher.mjs (the only networked module) is never invoked by tests; selftest | H9: living JEV: rhizome+parametric head, watch-deform-observe-idle-compile-serve, sealed promotion gate | I9: =COUNTIF(Parts!B5:B532,B9) -> 26 | J9: =COUNTIFS(Parts!B5:B532,B9,Parts!K5:K532,"<>") -> 26 | K9: =I9-J9 -> 0 | L9: =COUNTIFS(Parts!B5:B532,B9,Parts!E5:E532,0) -> 2 | M9: =COUNTIFS(Parts!B5:B532,B9,Parts!E5:E532,1) -> 10 | N9: =COUNTIFS(Parts!B5:B532,B9,Parts!E5:E532,2) -> 5 | O9: =COUNTIFS(Parts!B5:B532,B9,Parts!E5:E532,3) -> 6 | P9: =COUNTIFS(Parts!B5:B532,B9,Parts!E5:E532,4) -> 3 | R9: 0.7996
B10: jeviter | C10: garden | D10: /home/z/my-project/jeviter | E10: b8c5801 | F10: PASS 85/85 | G10: node --test auto-discovery, 0.7s, offline, zero deps. Additional dog-food: node examples/vibe-distill.js --check -> '[distill] --check re-verify: PASS' (3 pinne | H10: homeostatic iteration: rest-and-react on surprise, every silence receipted, living threshold ratchets | I10: =COUNTIF(Parts!B5:B532,B10) -> 24 | J10: =COUNTIFS(Parts!B5:B532,B10,Parts!K5:K532,"<>") -> 24 | K10: =I10-J10 -> 0 | L10: =COUNTIFS(Parts!B5:B532,B10,Parts!E5:E532,0) -> 2 | M10: =COUNTIFS(Parts!B5:B532,B10,Parts!E5:E532,1) -> 8 | N10: =COUNTIFS(Parts!B5:B532,B10,Parts!E5:E532,2) -> 7 | O10: =COUNTIFS(Parts!B5:B532,B10,Parts!E5:E532,3) -> 2 | P10: =COUNTIFS(Parts!B5:B532,B10,Parts!E5:E532,4) -> 5 | R10: 0.8523
B11: exoj | C11: garden | D11: /home/z/my-project/exoj | E11: a34ab8d | F11: PASS 3/3 | G11: Seedbox-inherited smoke (sha256 KAT, randomBytes, charter present), <1s, offline. Stronger second verdict: node experiments/e_x0_pocs.mjs -> EX0 VERDICT 8/8 PAS | H11: field is primary: non-collapsing hex-lattice scratch-paper, soft JEV writes, recorded observation, content-addressed proof | I11: =COUNTIF(Parts!B5:B532,B11) -> 26 | J11: =COUNTIFS(Parts!B5:B532,B11,Parts!K5:K532,"<>") -> 24 | K11: =I11-J11 -> 2 | L11: =COUNTIFS(Parts!B5:B532,B11,Parts!E5:E532,0) -> 4 | M11: =COUNTIFS(Parts!B5:B532,B11,Parts!E5:E532,1) -> 10 | N11: =COUNTIFS(Parts!B5:B532,B11,Parts!E5:E532,2) -> 4 | O11: =COUNTIFS(Parts!B5:B532,B11,Parts!E5:E532,3) -> 5 | P11: =COUNTIFS(Parts!B5:B532,B11,Parts!E5:E532,4) -> 3 | R11: 0.631
B12: fleet-seeds | C12: garden | D12: /home/z/my-project/fleet-seeds | E12: 8d875df | F12: PASS (1 commit, SMOKE OK 3/3, tree clean after cleanup) | G12: The offline mode exists: --selftest spawns a demo repo in .selftest/ (git init + first commit, no network), runs its smoke.mjs (3/3 green), then removes everyth | H12: the seedbox: seed.md -> rigor-at-birth repo whose first commit is charter law | I12: =COUNTIF(Parts!B5:B532,B12) -> 16 | J12: =COUNTIFS(Parts!B5:B532,B12,Parts!K5:K532,"<>") -> 15 | K12: =I12-J12 -> 1 | L12: =COUNTIFS(Parts!B5:B532,B12,Parts!E5:E532,0) -> 0 | M12: =COUNTIFS(Parts!B5:B532,B12,Parts!E5:E532,1) -> 1 | N12: =COUNTIFS(Parts!B5:B532,B12,Parts!E5:E532,2) -> 4 | O12: =COUNTIFS(Parts!B5:B532,B12,Parts!E5:E532,3) -> 4 | P12: =COUNTIFS(Parts!B5:B532,B12,Parts!E5:E532,4) -> 7 | R12: 0.6883
B13: quilt-murmur | C13: swarm | D13: /home/z/my-project/download/quilt-murmur | E13: 2a38044 | F13: SMOKE OK — 16/16 checks pass | G13: Offline, no API keys (MothVault degrades to labeled mock), <1s wall. Checks: engine reflex self-write, bus pool in (0,1) + zero-trust zero-influence, hedge lead | H13: Gossip trust economy: envelope + log-odds pooling, Hedge trust, provenance/admission gates, evolutionary gardener — every claim receipted | I13: =COUNTIF(Parts!B5:B532,B13) -> 28 | J13: =COUNTIFS(Parts!B5:B532,B13,Parts!K5:K532,"<>") -> 23 | K13: =I13-J13 -> 5 | L13: =COUNTIFS(Parts!B5:B532,B13,Parts!E5:E532,0) -> 3 | M13: =COUNTIFS(Parts!B5:B532,B13,Parts!E5:E532,1) -> 15 | N13: =COUNTIFS(Parts!B5:B532,B13,Parts!E5:E532,2) -> 6 | O13: =COUNTIFS(Parts!B5:B532,B13,Parts!E5:E532,3) -> 1 | P13: =COUNTIFS(Parts!B5:B532,B13,Parts!E5:E532,4) -> 3 | R13: 0.1372
B14: quilt-pincher | C14: swarm | D14: /home/z/my-project/quilt-pincher | E14: 15fcd53 | F14: 12/12 tests pass, 0 fail (5.2s, offline) | G14: node:test runner via tsx; covers direct-hit tier, confirm tier, compile tier (mock compiler), veto paths, confidence climb, PincherSheet composition, and the th | H14: Reflex engine built entirely from quilt cells: pinch, match, veto, execute — three latency tiers, LLM only as compiler | I14: =COUNTIF(Parts!B5:B532,B14) -> 18 | J14: =COUNTIFS(Parts!B5:B532,B14,Parts!K5:K532,"<>") -> 10 | K14: =I14-J14 -> 8 | L14: =COUNTIFS(Parts!B5:B532,B14,Parts!E5:E532,0) -> 3 | M14: =COUNTIFS(Parts!B5:B532,B14,Parts!E5:E532,1) -> 7 | N14: =COUNTIFS(Parts!B5:B532,B14,Parts!E5:E532,2) -> 3 | O14: =COUNTIFS(Parts!B5:B532,B14,Parts!E5:E532,3) -> 3 | P14: =COUNTIFS(Parts!B5:B532,B14,Parts!E5:E532,4) -> 2 | R14: 0.14
B15: crab-traps | C15: swarm | D15: /home/z/my-project/crab-traps | E15: 37c34bb | F15: 12/12 controls PASS, fail-closed (0.18s, stdlib-only, zero network) | G15: Negative controls T1-T8 (tampered stone bytes, wrong pins, flipped witness/artifact/prediction/fixture bytes, skipped middle receipt) each -> DISAGREE; POS unta | H15: Lures put foreign bots to work; canonical-JSON hash chains, consent plaque and honest economy make every catch and every tamper loud | I15: =COUNTIF(Parts!B5:B532,B15) -> 22 | J15: =COUNTIFS(Parts!B5:B532,B15,Parts!K5:K532,"<>") -> 16 | K15: =I15-J15 -> 6 | L15: =COUNTIFS(Parts!B5:B532,B15,Parts!E5:E532,0) -> 4 | M15: =COUNTIFS(Parts!B5:B532,B15,Parts!E5:E532,1) -> 8 | N15: =COUNTIFS(Parts!B5:B532,B15,Parts!E5:E532,2) -> 6 | O15: =COUNTIFS(Parts!B5:B532,B15,Parts!E5:E532,3) -> 2 | P15: =COUNTIFS(Parts!B5:B532,B15,Parts!E5:E532,4) -> 2 | R15: 0.1329
B16: quilt-organ-workers | C16: organ | D16: /home/z/my-project/quilt-organ-workers | E16: 45f4768 | F16: NOT_RUN | G16: Reason: CF worker requires deploy — scripts/deploy.sh authenticates to the Cloudflare REST API (token verify, KV namespace, script upload, cron schedules) and t | H16: Three Cloudflare workers: content-addressed organ store, independent drift watcher, judge relay. | I16: =COUNTIF(Parts!B5:B532,B16) -> 20 | J16: =COUNTIFS(Parts!B5:B532,B16,Parts!K5:K532,"<>") -> 19 | K16: =I16-J16 -> 1 | L16: =COUNTIFS(Parts!B5:B532,B16,Parts!E5:E532,0) -> 3 | M16: =COUNTIFS(Parts!B5:B532,B16,Parts!E5:E532,1) -> 4 | N16: =COUNTIFS(Parts!B5:B532,B16,Parts!E5:E532,2) -> 5 | O16: =COUNTIFS(Parts!B5:B532,B16,Parts!E5:E532,3) -> 4 | P16: =COUNTIFS(Parts!B5:B532,B16,Parts!E5:E532,4) -> 4 | R16: 0.1025
B17: quilt-jev-toolkit | C17: organ | D17: /home/z/my-project/quilt-jev-toolkit | E17: c9840b2 | F17: PASS 44/44 (145ms) + boot-demo PASS + rewind-demo 7/7 stages PASS (all offline) | G17: Suite = 34 v0/v1 tests untouched + 10 v2 (signed checkpoints, partial custody). Demos re-ran fresh this lane and wrote their receipts (examples/receipts/boot-de | H17: Organ protocol v0→v2: verified custody bundles, rewind family, double-entry nesting, signed checkpoints. | I17: =COUNTIF(Parts!B5:B532,B17) -> 25 | J17: =COUNTIFS(Parts!B5:B532,B17,Parts!K5:K532,"<>") -> 25 | K17: =I17-J17 -> 0 | L17: =COUNTIFS(Parts!B5:B532,B17,Parts!E5:E532,0) -> 4 | M17: =COUNTIFS(Parts!B5:B532,B17,Parts!E5:E532,1) -> 7 | N17: =COUNTIFS(Parts!B5:B532,B17,Parts!E5:E532,2) -> 8 | O17: =COUNTIFS(Parts!B5:B532,B17,Parts!E5:E532,3) -> 3 | P17: =COUNTIFS(Parts!B5:B532,B17,Parts!E5:E532,4) -> 3 | R17: 0.086
B18: quilt-mcp-receipts | C18: organ | D18: /home/z/my-project/quilt-mcp-receipts | E18: 889960a | F18: PASS 15/15 (5.6s, offline) | G18: Every test spawns a real server process and speaks newline-delimited JSON-RPC over stdio; the test signer is re-derived from DESIGN.md §2, not imported from ser | H18: Fleet receipt chain as signed append-only MCP organ; fail-closed named errors. | I18: =COUNTIF(Parts!B5:B532,B18) -> 16 | J18: =COUNTIFS(Parts!B5:B532,B18,Parts!K5:K532,"<>") -> 16 | K18: =I18-J18 -> 0 | L18: =COUNTIFS(Parts!B5:B532,B18,Parts!E5:E532,0) -> 4 | M18: =COUNTIFS(Parts!B5:B532,B18,Parts!E5:E532,1) -> 4 | N18: =COUNTIFS(Parts!B5:B532,B18,Parts!E5:E532,2) -> 3 | O18: =COUNTIFS(Parts!B5:B532,B18,Parts!E5:E532,3) -> 3 | P18: =COUNTIFS(Parts!B5:B532,B18,Parts!E5:E532,4) -> 2 | R18: 0.0949
B19: quilt-research-canons | C19: organ | D19: /home/z/my-project/quilt-research-canons | E19: 3547d01 | F19: PASS — 5/5 sprint scripts fully conform to the SPRINT-LINEAGE contract; 3/3 JSON artifacts parse | G19: The sprint scripts themselves were NOT executed: they require API keys (env TYPESAFEAI_KEY etc.) and network calls to api.typesafe.ai / api.deepinfra.com (sprin | H19: Research canon documents: sprint-lineage protocol, pre-registered predictions, witnesses declaring successors. | I19: =COUNTIF(Parts!B5:B532,B19) -> 14 | J19: =COUNTIFS(Parts!B5:B532,B19,Parts!K5:K532,"<>") -> 9 | K19: =I19-J19 -> 5 | L19: =COUNTIFS(Parts!B5:B532,B19,Parts!E5:E532,0) -> 2 | M19: =COUNTIFS(Parts!B5:B532,B19,Parts!E5:E532,1) -> 3 | N19: =COUNTIFS(Parts!B5:B532,B19,Parts!E5:E532,2) -> 4 | O19: =COUNTIFS(Parts!B5:B532,B19,Parts!E5:E532,3) -> 2 | P19: =COUNTIFS(Parts!B5:B532,B19,Parts!E5:E532,4) -> 3 | R19: 0.1031
B20: quilt-quant | C20: labs | D20: /home/z/my-project/download/quilt-quant | E20: c20c1c8 | F20: PASS (17/17 checks green, 220ms, offline mode) | G20: Offline skips the 2 live-channel checks (19 live). Two local fixes were needed, no network used: (1) missing 'yaml' dep satisfied by symlink download/node_modul | H20: Trading desk as closed-loop cell sheet: simulate first, gated learning, receipts. | I20: =COUNTIF(Parts!B5:B532,B20) -> 14 | J20: =COUNTIFS(Parts!B5:B532,B20,Parts!K5:K532,"<>") -> 13 | K20: =I20-J20 -> 1 | L20: =COUNTIFS(Parts!B5:B532,B20,Parts!E5:E532,0) -> 2 | M20: =COUNTIFS(Parts!B5:B532,B20,Parts!E5:E532,1) -> 4 | N20: =COUNTIFS(Parts!B5:B532,B20,Parts!E5:E532,2) -> 4 | O20: =COUNTIFS(Parts!B5:B532,B20,Parts!E5:E532,3) -> 2 | P20: =COUNTIFS(Parts!B5:B532,B20,Parts!E5:E532,4) -> 2 | R20: 0.717
B21: quilt-dba | C21: labs | D21: /home/z/my-project/download/quilt-dba | E21: 7113eed | F21: PASS (13/13 checks) | G21: Honest negative: the repo-root `node smoke.mjs` FAILS (dba/driver.mjs:20 imports TASKS from dba/sheet.mjs which no longer exports it — SyntaxError). The canonic | H21: Developmental agent as 12-cell seed sheet: growth, conservation law, honest gates. | I21: =COUNTIF(Parts!B5:B532,B21) -> 15 | J21: =COUNTIFS(Parts!B5:B532,B21,Parts!K5:K532,"<>") -> 15 | K21: =I21-J21 -> 0 | L21: =COUNTIFS(Parts!B5:B532,B21,Parts!E5:E532,0) -> 3 | M21: =COUNTIFS(Parts!B5:B532,B21,Parts!E5:E532,1) -> 5 | N21: =COUNTIFS(Parts!B5:B532,B21,Parts!E5:E532,2) -> 3 | O21: =COUNTIFS(Parts!B5:B532,B21,Parts!E5:E532,3) -> 2 | P21: =COUNTIFS(Parts!B5:B532,B21,Parts!E5:E532,4) -> 2 | R21: 0.7387
B22: quilt-raw | C22: labs | D22: /home/z/my-project/download/quilt-raw | E22: e759163 | F22: PASS (18/18 checks sealed) | G22: Covers q32 arithmetic vs reference (i128>>32 wrap mul, truncating div, exact isqrt), tick 7-ops + ledger, transactional breach halt with ledger bit-unchanged, 5 | H22: v -> L -> G -> v' in exact integer arithmetic: seven ops, exact rewind, no search. | I22: =COUNTIF(Parts!B5:B532,B22) -> 14 | J22: =COUNTIFS(Parts!B5:B532,B22,Parts!K5:K532,"<>") -> 12 | K22: =I22-J22 -> 2 | L22: =COUNTIFS(Parts!B5:B532,B22,Parts!E5:E532,0) -> 2 | M22: =COUNTIFS(Parts!B5:B532,B22,Parts!E5:E532,1) -> 8 | N22: =COUNTIFS(Parts!B5:B532,B22,Parts!E5:E532,2) -> 0 | O22: =COUNTIFS(Parts!B5:B532,B22,Parts!E5:E532,3) -> 1 | P22: =COUNTIFS(Parts!B5:B532,B22,Parts!E5:E532,4) -> 3 | R22: 0.661
B23: cot-quilt | C23: labs | D23: /home/z/my-project/cot-quilt | E23: 0f360b9 | F23: PASS (offline ritual: verdict CLEAN, exit 0) + live pipeline NOT_RUN | G23: Live run needs DEEPSEEK/TYPESAFE/DEEPINFRA keys and network — forbidden by dog-food rules, so NOT_RUN with that reason. The offline credential scanner is green: | H23: Cheap models decompose a big model's CoT into a receipted cellular graph. | I23: =COUNTIF(Parts!B5:B532,B23) -> 12 | J23: =COUNTIFS(Parts!B5:B532,B23,Parts!K5:K532,"<>") -> 9 | K23: =I23-J23 -> 3 | L23: =COUNTIFS(Parts!B5:B532,B23,Parts!E5:E532,0) -> 1 | M23: =COUNTIFS(Parts!B5:B532,B23,Parts!E5:E532,1) -> 4 | N23: =COUNTIFS(Parts!B5:B532,B23,Parts!E5:E532,2) -> 3 | O23: =COUNTIFS(Parts!B5:B532,B23,Parts!E5:E532,3) -> 2 | P23: =COUNTIFS(Parts!B5:B532,B23,Parts!E5:E532,4) -> 2 | R23: 0.8006
B24: MicroMoth-quilt | C24: labs | D24: /home/z/my-project/MicroMoth-quilt | E24: b23055c | F24: PARTIAL (19 passed, 1 failed) | G24: Honest negative, and the failure is the design working: test_manifest_exists_and_matches FAILED because the tracked tree drifted AFTER the import-baseline manif | H24: Smallest quantum framework taught to keep receipts: circuit = hash-chained cell ledger. | I24: =COUNTIF(Parts!B5:B532,B24) -> 13 | J24: =COUNTIFS(Parts!B5:B532,B24,Parts!K5:K532,"<>") -> 10 | K24: =I24-J24 -> 3 | L24: =COUNTIFS(Parts!B5:B532,B24,Parts!E5:E532,0) -> 2 | M24: =COUNTIFS(Parts!B5:B532,B24,Parts!E5:E532,1) -> 5 | N24: =COUNTIFS(Parts!B5:B532,B24,Parts!E5:E532,2) -> 2 | O24: =COUNTIFS(Parts!B5:B532,B24,Parts!E5:E532,3) -> 2 | P24: =COUNTIFS(Parts!B5:B532,B24,Parts!E5:E532,4) -> 2 | R24: 0.766
B25: moth-research | C25: labs | D25: /home/z/my-project/moth-research | E25: c20c1c8 | F25: NOT_RUN (no executable entry point — docs-only research mooring) | G25: The repo is offline HTML snapshots of the Moth Quantum API docs (intro, endpoints, 7 engine pages), the vendored MicroMoth source, and the vendored quantum-audi | H25: Vendored quantum API docs + offline twins: the sourcing discipline behind lab entropy. | I25: =COUNTIF(Parts!B5:B532,B25) -> 10 | J25: =COUNTIFS(Parts!B5:B532,B25,Parts!K5:K532,"<>") -> 6 | K25: =I25-J25 -> 4 | L25: =COUNTIFS(Parts!B5:B532,B25,Parts!E5:E532,0) -> 2 | M25: =COUNTIFS(Parts!B5:B532,B25,Parts!E5:E532,1) -> 3 | N25: =COUNTIFS(Parts!B5:B532,B25,Parts!E5:E532,2) -> 2 | O25: =COUNTIFS(Parts!B5:B532,B25,Parts!E5:E532,3) -> 2 | P25: =COUNTIFS(Parts!B5:B532,B25,Parts!E5:E532,4) -> 1 | R25: 0.7344
B26: superinstance-site | C26: meta | D26: /home/z/my-project/download/superinstance | E26: c20c1c8 | F26: PASS | G26: 4 embedded script blocks extracted (4832/12981/21103/1988 bytes); largest parses clean under node --check. Full page NOT_RUN in DOM (needs headless Chromium; th | H26: the account's public face: brand, positioning map, QA manifesto — running cells instead of screenshots | I26: =COUNTIF(Parts!B5:B532,B26) -> 19 | J26: =COUNTIFS(Parts!B5:B532,B26,Parts!K5:K532,"<>") -> 10 | K26: =I26-J26 -> 9 | L26: =COUNTIFS(Parts!B5:B532,B26,Parts!E5:E532,0) -> 2 | M26: =COUNTIFS(Parts!B5:B532,B26,Parts!E5:E532,1) -> 5 | N26: =COUNTIFS(Parts!B5:B532,B26,Parts!E5:E532,2) -> 5 | O26: =COUNTIFS(Parts!B5:B532,B26,Parts!E5:E532,3) -> 3 | P26: =COUNTIFS(Parts!B5:B532,B26,Parts!E5:E532,4) -> 4 | R26: 0.067
B27: quilt-upstream | C27: meta | D27: /home/z/my-project/quilt-upstream-main | E27: fdfed69 | F27: PASS | G27: Upstream engine core: 4 test files, 36/36 passed in 954ms, fully offline (vitest resolved from the repo's own node_modules). Also python3 -m py_compile quilt-ke | H27: the upstream quilt repo (external origin, Lucineer): the engine core the fleet knows, plus an out-of-superinstance idea corpus of essays and papers | I27: =COUNTIF(Parts!B5:B532,B27) -> 24 | J27: =COUNTIFS(Parts!B5:B532,B27,Parts!K5:K532,"<>") -> 9 | K27: =I27-J27 -> 15 | L27: =COUNTIFS(Parts!B5:B532,B27,Parts!E5:E532,0) -> 2 | M27: =COUNTIFS(Parts!B5:B532,B27,Parts!E5:E532,1) -> 11 | N27: =COUNTIFS(Parts!B5:B532,B27,Parts!E5:E532,2) -> 7 | O27: =COUNTIFS(Parts!B5:B532,B27,Parts!E5:E532,3) -> 0 | P27: =COUNTIFS(Parts!B5:B532,B27,Parts!E5:E532,4) -> 4 | R27: 0.1609
B28: breakthrough-prospector | C28: meta | D28: /home/z/my-project/breakthrough-prospector | E28: f0034fd | F28: PASS | G28: The scorer RAN offline and emitted the live table: E1 80 RUN (bug-injection self-play), E6 64 RUN, E3 60 RUN with '! F cap: external dependency (Casey)', E7 60 | H28: a pipeline that turns frontier scouting into pre-registered, receipt-backed experiments — crossing abstractions systematically instead of by luck at 3am | I28: =COUNTIF(Parts!B5:B532,B28) -> 16 | J28: =COUNTIFS(Parts!B5:B532,B28,Parts!K5:K532,"<>") -> 9 | K28: =I28-J28 -> 7 | L28: =COUNTIFS(Parts!B5:B532,B28,Parts!E5:E532,0) -> 2 | M28: =COUNTIFS(Parts!B5:B532,B28,Parts!E5:E532,1) -> 5 | N28: =COUNTIFS(Parts!B5:B532,B28,Parts!E5:E532,2) -> 5 | O28: =COUNTIFS(Parts!B5:B532,B28,Parts!E5:E532,3) -> 2 | P28: =COUNTIFS(Parts!B5:B532,B28,Parts!E5:E532,4) -> 2 | R28: 0.5179
B29: craftmind-study | C29: meta | D29: /home/z/my-project/craftmind-study | E29: c20c1c8 | F29: PASS | G29: Core ranch modules parse clean. Test suites NOT_RUN: tests/test-all.js + integration tests target a Worker/runtime harness not present offline; live instances a | H29: study of three sibling Cocapn-fleet experiments where learning is emergent and verified-work-only: evolving ranch bots, a blank-slate researcher, correction-trained sheepdogs | I29: =COUNTIF(Parts!B5:B532,B29) -> 16 | J29: =COUNTIFS(Parts!B5:B532,B29,Parts!K5:K532,"<>") -> 5 | K29: =I29-J29 -> 11 | L29: =COUNTIFS(Parts!B5:B532,B29,Parts!E5:E532,0) -> 3 | M29: =COUNTIFS(Parts!B5:B532,B29,Parts!E5:E532,1) -> 5 | N29: =COUNTIFS(Parts!B5:B532,B29,Parts!E5:E532,2) -> 6 | O29: =COUNTIFS(Parts!B5:B532,B29,Parts!E5:E532,3) -> 1 | P29: =COUNTIFS(Parts!B5:B532,B29,Parts!E5:E532,4) -> 1 | R29: 0.4297
B30: quilt-atlas | C30: meta | D30: /home/z/my-project/quilt-atlas | E30: 5aa850d | F30: PASS | G30: Generator parses clean. Full re-inventory NOT_RUN: requires GITHUB_TOKEN and network (per README usage), both out of scope for this lane. atlas.json itself was | H30: prior atlas: a 6h scheduled re-inventory of the account with auditable classification and honest UNMEASURED vocabulary — superseded by wave-66, which decomposes ideas, not repo surfaces | I30: =COUNTIF(Parts!B5:B532,B30) -> 12 | J30: =COUNTIFS(Parts!B5:B532,B30,Parts!K5:K532,"<>") -> 6 | K30: =I30-J30 -> 6 | L30: =COUNTIFS(Parts!B5:B532,B30,Parts!E5:E532,0) -> 2 | M30: =COUNTIFS(Parts!B5:B532,B30,Parts!E5:E532,1) -> 2 | N30: =COUNTIFS(Parts!B5:B532,B30,Parts!E5:E532,2) -> 3 | O30: =COUNTIFS(Parts!B5:B532,B30,Parts!E5:E532,3) -> 1 | P30: =COUNTIFS(Parts!B5:B532,B30,Parts!E5:E532,4) -> 4 | R30: 0.315
B31: quilt-codespace | C31: meta | D31: /home/z/my-project/quilt-codespace | E31: c8355d6 | F31: PASS | G31: The HTTP API server parses clean. Booting the three-service stack NOT_RUN: it is a Codespace deployment (ttyd + HTTP + dashboard via post-create.sh) and the scr | H31: codespace lane: quilt as a live token-authenticated federated runtime in a browser-terminal Codespace, subscribing to ESP32/Jetson/Cloud siblings | I31: =COUNTIF(Parts!B5:B532,B31) -> 14 | J31: =COUNTIFS(Parts!B5:B532,B31,Parts!K5:K532,"<>") -> 3 | K31: =I31-J31 -> 11 | L31: =COUNTIFS(Parts!B5:B532,B31,Parts!E5:E532,0) -> 2 | M31: =COUNTIFS(Parts!B5:B532,B31,Parts!E5:E532,1) -> 4 | N31: =COUNTIFS(Parts!B5:B532,B31,Parts!E5:E532,2) -> 3 | O31: =COUNTIFS(Parts!B5:B532,B31,Parts!E5:E532,3) -> 4 | P31: =COUNTIFS(Parts!B5:B532,B31,Parts!E5:E532,4) -> 1 | R31: 0.2474
B32: si-fleet | C32: meta | D32: /home/z/my-project/si-fleet | E32: c20c1c8 | F32: PASS | G32: tidepool suite runs fully offline on mocks: 'tide-pool smoke: 18 passed, 0 failed' + node:test 13/13 pass (98ms) covering JEV gate floor refusal, sigma agreemen | H32: fleet infrastructure as one monorepo of lanes: a shared context ocean, edge quilt runtimes, AI cells, canon headers | I32: =COUNTIF(Parts!B5:B532,B32) -> 16 | J32: =COUNTIFS(Parts!B5:B532,B32,Parts!K5:K532,"<>") -> 8 | K32: =I32-J32 -> 8 | L32: =COUNTIFS(Parts!B5:B532,B32,Parts!E5:E532,0) -> 2 | M32: =COUNTIFS(Parts!B5:B532,B32,Parts!E5:E532,1) -> 4 | N32: =COUNTIFS(Parts!B5:B532,B32,Parts!E5:E532,2) -> 5 | O32: =COUNTIFS(Parts!B5:B532,B32,Parts!E5:E532,3) -> 3 | P32: =COUNTIFS(Parts!B5:B532,B32,Parts!E5:E532,4) -> 2 | R32: 0.0698
B33: external-scouts | C33: meta | D33: /home/z/my-project/jev-garden/scouts/raw | E33: d05e1d9 | F33: PASS | G33: All 5 raw scout JSONs parse: V-JEPA_2_JEPA_world_mode.json (4 results), test-time_training_layer.json (7), knowledge_distillation_L.json (7), hyperdimensional_c | H33: out-of-superinstance research moorings: five raw web-search receipts the garden synthesized into design justifications — one channel returned junk and was receipted, not hidden | I33: =COUNTIF(Parts!B5:B532,B33) -> 17 | J33: =COUNTIFS(Parts!B5:B532,B33,Parts!K5:K532,"<>") -> 5 | K33: =I33-J33 -> 12 | L33: =COUNTIFS(Parts!B5:B532,B33,Parts!E5:E532,0) -> 1 | M33: =COUNTIFS(Parts!B5:B532,B33,Parts!E5:E532,1) -> 4 | N33: =COUNTIFS(Parts!B5:B532,B33,Parts!E5:E532,2) -> 9 | O33: =COUNTIFS(Parts!B5:B532,B33,Parts!E5:E532,3) -> 1 | P33: =COUNTIFS(Parts!B5:B532,B33,Parts!E5:E532,4) -> 2 | R33: 0.3726

Sheet Parts
B2: Elementary parts (528 rows — spreadsheet logic)
B4: work | C4: family | D4: part_id | E4: layer | F4: layer_name | G4: name | H4: essence | I4: inputs | J4: outputs | K4: gate | L4: gate_kind | M4: failure_mode | N4: elementary | O4: evidence
B5: qthe | C5: substrate | D5: qthe-P01 | E5: 0 | F5: substrate | G5: pack/unpack bijection over one byte | H5: c <-> (tau, d) is an exact bijection onto {0..3} x {0..63}; bit 7-6 tau, bit 5-0 d. | I5: tau, d | J5: packed byte c, unpacked {tau,d} | K5: 256/256 values round-trip exact AND 256 distinct packed outputs (gate G1) | L5: postcondition | M5: any overlap or lossy round-trip would break every downstream trace hash | N5: yes | O5: qthe.mjs:66-69
B6: qthe | C6: substrate | D6: qthe-P02 | E6: 0 | F6: substrate | G6: Psi operator map | H6: The timbre-to-operator character table {0:0, 1:+1, 2:-1, 3:'i'} — Ground contributes to nothing, Attract amplifies, Repel inverts, Abstain is the looking-glass. | I6: tau | J6: operator character 0 | +1 | -1 | 'i' | K6: PSI === [0, 1, -1, 'i'] asserted by G1 | L6: invariant | N6: yes | O6: qthe.mjs:58-63
B7: qthe | C7: substrate | D7: qthe-P03 | E7: 0 | F7: substrate | G7: split-channel vector pass (integer-exact) | H7: y_j^R = sum(Attract d*x) - sum(Repel d*x), y_j^I = sum(Abstain d*x); Ground excluded even with d>0; no floats in LAYER 0. | I7: weights rows of packed bytes, integer xs | J7: {re, im} per output channel j | K7: hand-computed fixtures exact and every output Number.isInteger (G4: row0 [A10,R4,I6,G63] x xs[2,3,5,7] -> {re:8, im:30}) | L7: postcondition | M7: float leakage or a wrong channel assignment would fail the literal fixtures | N7: yes | O7: qthe.mjs:77-95
B8: qthe | C8: substrate | D8: qthe-P04 | E8: 0 | F8: substrate | G8: substrate allocation with named expandos | H8: makeSubstrate returns a Uint8Array carrying w, h, ticks, __wormholes and bytes as named properties; serialize via traceView, never JSON.stringify. | I8: w, h, seedFn(x,y,i) | J8: row-major packed cell plane | K8: w, h positive integers else RangeError | L8: precondition | M8: JSON.stringify would leak expandos into traces (receipted as R5) | N8: yes | O8: qthe.mjs:148-160
B9: qthe | C9: substrate | D9: qthe-P05 | E9: 1 | F9: mechanism | G9: 64-slot wormhole table | H9: Static allocation, zero runtime discovery: slot s is empty or {x, y, resonance}; sigma parameter default log2(3). | I9: sigma | J9: read(slot), write(slot,x,y,resonance), snapshot() | K9: exactly SLOT_COUNT=64 slots; write outside [0,64) throws RangeError | L9: invariant | N9: yes | O9: qthe.mjs:99-142
B10: qthe | C10: substrate | D10: qthe-P06 | E10: 1 | F10: mechanism | G10: twin-resonance read guard | H10: An Abstain cell with data d reads slot d live; a hit counts only if the occupant is a different (x,y) with resonance != 0; the term resonance*sigma is added to pressure and emitted as an event. | I10: slot=d of the Abstain cell, wormhole table | J10: pressure adjustment, twin event {kind,x,y,slot,resonance,term} | K10: lone Abstain cell never twins after its own first write; every event term === log2(3) exactly (G5 schedule) | L10: postcondition | M10: self-resonance (same x,y) or resonance=0 would make single cells self-excite | N10: yes | O10: qthe.mjs:217-224
B11: qthe | C11: substrate | D11: qthe-P07 | E11: 1 | F11: mechanism | G11: wormhole write, last-writer-wins | H11: After pressure, an Abstain cell writes its own (x, y) and resonance = |real_acc| + 1 to slot d; collisions resolve last-writer-wins while live reads keep same-slot twins mutually audible. | I11: x, y, |acc|+1, slot=d | J11: occupied slot, totalWrites++ | K11: totalWrites = 12 after the G5 6-tick twin fixture | L11: postcondition | N11: yes | O11: qthe.mjs:123-128, 224
B12: qthe | C12: substrate | D12: qthe-P08 | E12: 2 | F12: policy | G12: sigma bridge scale policy | H12: sigma defaults to log2(3) but is a swept parameter: with sigma~1.585 a lone twin flips exactly one unit of net-negative pressure, so the C3 sweep is a real dynamics sweep, not decoration. | I12: sigma override | J12: imaginary pressure scale | K12: the SPEC prices sigma as OPEN: only the sweep {log2(3), 0.5, 1, 2, 4} decides (C3); the gifted 'proof' is receipted as decorative | L12: budget | M12: treating log2(3) as proven would be LARP; SPEC.md receipted it as decorative | N12: yes | O12: qthe.mjs:100, 28-35; SPEC.md:75
B13: qthe | C13: substrate | D13: qthe-P09 | E13: 1 | F13: mechanism | G13: pre-tick snapshot double buffer | H13: Neighbors are always read from the pre-tick grid so in-place update stays synchronous-exact (interpretation receipt R2/R6). | I13: current cells | J13: snap copy reused via __scratch | K13: tick mutates in place and returns the same substrate with synchronous-exact semantics | L13: invariant | N13: yes | O13: qthe.mjs:172-194
B14: qthe | C14: substrate | D14: qthe-P10 | E14: 1 | F14: mechanism | G14: Moore-8 branchless real accumulator | H14: Eight toroidal neighbor reads in fixed order: Attract adds d, Repel subtracts d into the real accumulator; fixed order is what makes the wormhole live-read deterministic. | I14: snap, x, y | J14: integer acc in [-504, 504] | K14: G2 full-tick exhaustion: 3840/3840 cell-updates in bounds with tau preserved | L14: invariant | N14: yes | O14: qthe.mjs:197-214
B15: qthe | C15: substrate | D15: qthe-P11 | E15: 1 | F15: mechanism | G15: nextD saturation rule | H15: Pure rule table: net-positive pressure moves d toward min(d+1, 63), net-negative toward 0, zero leaves d unchanged. | I15: d, pressure | J15: new d in [0,63] | K15: 2304/2304 exhausted states x 9 pressures stay in [0,63] (G2a — the Coq theorem restated by exhaustion) | L15: postcondition | N15: yes | O15: qthe.mjs:166-170
B16: qthe | C16: substrate | D16: qthe-P12 | E16: 1 | F16: mechanism | G16: timbre frozen inside tick | H16: tau never changes inside tick — timbre is written only by injectors — which keeps the C2 paired arms clean and the byte's only dynamics in d. | I16: cell byte | J16: cell byte with identical tau | K16: G2: tau preserved EXACTLY on 3840/3840 updates | L16: invariant | M16: any tau mutation inside tick would contaminate the paired-arm C2 comparison | N16: yes | O16: qthe.mjs:163-165, 226
B17: qthe | C17: substrate | D17: qthe-P13 | E17: 1 | F17: mechanism | G17: toroidal Moore-8 edges (R1) | H17: Edges wrap, so every cell has exactly 8 neighbors and the update rule is one uniform table with no boundary special case. | I17: w, h | J17: wrap indices (y+h-1)%h, (x+1)%w, ... | N17: yes | O17: qthe.mjs:18-19, 198-205
B18: qthe | C18: substrate | D18: qthe-P14 | E18: 1 | F18: mechanism | G18: determinism contract: no Math.random in the kernel | H18: mulberry32 exists only as a SEEDED caller-side generator; tick never draws randomness; same substrate + same opts is byte-identical. | I18: substrate, opts | J18: deterministic advanced substrate | K18: G3: two substrates, 1000 ticks, all per-tick trace hashes byte-identical; different seed differs; static scan finds ZERO Math.random in the kernel | L18: seal | M18: a nondeterministic tick would void every experiment (determinism or it didn't happen) | N18: yes | O18: qthe.mjs:10-13, 253-265
B19: qthe | C19: substrate | D19: qthe-P15 | E19: 3 | F19: interface | G19: traceView canonical serialization | H19: The single JSON-able view of substrate + table + tick events that G3/G6 hash and the A2UI HUD displays; expandos never enter the view and wormhole STATE is recorded, not the flag (R7). | I19: cells, events | J19: {w,h,ticks,cells,wormholes,events} | K19: an empty table is trace-equivalent to wormholes disabled; paired arms byte-equal with zero Abstain cells (G6/S2) | L19: invariant | M19: R7: on the first G6 run the flag itself leaked into traces — found by the gate and receipted | N19: yes | O19: qthe.mjs:243-251
B20: qthe | C20: substrate | D20: qthe-P16 | E20: 2 | F20: policy | G20: paired-arm wormholes flag | H20: opts.wormholes=false disables table reads AND writes (the OFF arm); without Abstain cells the flag must not leak into dynamics at all. | I20: opts.wormholes, substrate | J20: ON/OFF arm pair for C2 | K20: G6/S1: ON-trace != OFF-trace (divergence tick exists); G6/S2: with zero Abstain cells ON === OFF byte-identical at all 200 ticks | L20: postcondition | N20: yes | O20: qthe.mjs:175-190; SPEC.md:74
B21: qthe | C21: substrate | D21: qthe-P17 | E21: 4 | F21: evidence | G21: pre-registered gate predictions G0-G6 | H21: Each gate's prediction is written into the test header BEFORE the first run, per house law; the run records observed numbers; exit 0 iff all gates PASS. | I21: qthe.mjs kernel | J21: tests/receipt.json verdicts + observed | K21: honest FAILs stay in the receipt chain, never rewritten | L21: seal | N21: yes | O21: tests/run_tests.mjs:1-9, 79-80
B22: qthe | C22: substrate | D22: qthe-P18 | E22: 4 | F22: evidence | G22: stone-v1 receipt chain for tests | H22: A receipt without a chain is a rumor: G1-G6 seal into tests/receipts.jsonl with observed numbers, fully deterministic so a re-run rewrites identical bytes. | I22: gate results | J22: receipt.json + receipts.jsonl stone chain | K22: re-run produces byte-identical receipts | L22: seal | N22: yes | O22: qthe.mjs:53-54; tests/run_tests.mjs:78-80
B23: qthe | C23: substrate | D23: qthe-P19 | E23: 4 | F23: evidence | G23: honest-FAIL preservation (G4 erratum) | H23: G4's pre-registered re-literal contained a hand-arithmetic error; the gate FAILS BY LETTER forever and the corrected literal is checked by a post-hoc gate G4-P2 — prediction was wrong, not the kernel; registered gates are never rewritten. | I23: registered G4 literal | J23: standing FAIL + erratum + correction gate | K23: the registered literal is never edited post-registration | L23: invariant | M23: rewriting the registered gate would be tampering with the pre-registration discipline | N23: yes | O23: tests/run_tests.mjs:38-46
B24: qthe | C24: substrate | D24: qthe-P20 | E24: 4 | F24: evidence | G24: two-reader negative controls | H24: An independent stdlib-only reader walks registered receipt chains and must fail closed: one flipped byte in every row localizes to exactly that row (49/49), plus missing-file, wrong-tip, unknown-chain and mutated-pin-table refusals. | I24: registered chains, pin table with seal | J24: self-test receipt {cases_total:54, escapes:0} | K24: exit 0 iff every negative control was DETECTED and localized to the correct row | L24: postcondition | M24: any escape (tamper passing silently) is the named catastrophe this part exists to refuse | N24: yes | O24: two_reader/selftest.mjs:6-22; two_reader/verdict.md:1-10
B25: qthe | C25: substrate | D25: qthe-P21 | E25: 2 | F25: policy | G25: priced empirical claims C1-C5 | H25: Layer-2 claims from the gifted corpus (gain of function, wormhole vs traversal, sigma criticality, phase threshold, self-repair) are pre-registered as paired arms with floors — all OPEN, honest null is a crown jewel. | I25: paired-arm experiment designs | J25: claim status table | K25: a claim that dies dies cheap and honest with the receipt kept beside the body; a claim that lives owes a mechanism-level explanation | L25: admission | M25: C3's gifted 'proof' is receipted as decorative (the Gaussian integral yields sigma*sqrt(2pi) for ANY sigma) — only the sweep decides | N25: yes | O25: SPEC.md:69-81
B26: qthe | C26: substrate | D26: qthe-P22 | E26: 3 | F26: interface | G26: A2UI telemetry mapping | H26: The live mirror: pixel = cell, tau=1 green, tau=2 red, tau=0 gray, tau=3 purple blinking on wormhole activity, 6-bit value = intensity, direct buffer-to-canvas, no log files. | I26: substrate bytes | J26: canvas pixels | K26: HUD SHA stable across reload (demo/smoke screenshots receipted) | L26: postcondition | N26: yes | O26: SPEC.md:65-67; demo/smoke/smoke.md:17 (checklist item c: HUD sha stable across reloads, cross-runtime MATCH)
B27: quilt-jepa | C27: substrate | D27: quilt-jepa-P01 | E27: 0 | F27: substrate | G27: xorshift32 deterministic seed | H27: The only randomness source: a 32-bit xorshift generator; seed 0 is coerced to the golden-ratio constant so seed space is total. | I27: u32 seed | J27: deterministic [0,1) stream | K27: no Math.random anywhere in core (determinism claim P4 PASS) | L27: invariant | M27: any hidden nondeterminism voids every byte-exact cross-round binding | N27: yes | O27: core/world.js:6-15
B28: quilt-jepa | C28: substrate | D28: quilt-jepa-P02 | E28: 0 | F28: substrate | G28: wave + ball observation field | H28: A 16x16 luminance field from two phased sinusoids plus a 2x2 ball bump clipped to 1 — the entire observable universe of the world model. | I28: world state (phases, freq, ball) | J28: Float32Array 256 luminances in [0,1] | K28: values are projections in [0,1] (v*0.5+0.5, min(1, ...)) | L28: invariant | N28: yes | O28: core/world.js:39-56
B29: quilt-jepa | C29: substrate | D29: quilt-jepa-P03 | E29: 0 | F29: substrate | G29: per-cell 4-dim features | H29: The local observable: [luminance, right-diff, down-diff, luminance-0.5] — the features each cell's encoder reads. | I29: obs, cell index i | J29: 4-vector f | N29: yes | O29: core/jepa.js:16-23
B30: quilt-jepa | C30: substrate | D30: quilt-jepa-P04 | E30: 1 | F30: mechanism | G30: per-cell context encoder Wc | H30: One 4x4 matrix per cell (Float32Array CELLS*16), xorshift-seeded at scale 0.5; encode maps features to the cell's latent. | I30: obs features per cell | J30: context latents z (CELLS x 4) | N30: yes | O30: core/jepa.js:34-47, 48-56
B31: quilt-jepa | C31: substrate | D31: quilt-jepa-P05 | E31: 1 | F31: mechanism | G31: per-cell predictor Wp | H31: One 4x4 matrix per cell predicting the next latent from the current context latent — the JEPA's learned dynamics. | I31: z_ctx | J31: z_pred | N31: yes | O31: core/jepa.js:66-73
B32: quilt-jepa | C32: substrate | D32: quilt-jepa-P06 | E32: 1 | F32: mechanism | G32: EMA target encoder Wt (stop-gradient) | H32: Wt = tau*Wt + (1-tau)*Wc with tau=0.999 (later pace-aware), providing the stable target the encoder chases — the law that prevents representation collapse. | I32: Wc, tau | J32: Wt target latents | K32: stationarity drift < 0.01 (claim R2v4 PASS, drift 2.640e-3) | L32: postcondition | M32: an unstable target would let the encoder chase itself into collapse | N32: yes | O32: core/jepa.js:39-46, 110-113
B33: quilt-jepa | C33: substrate | D33: quilt-jepa-P07 | E33: 1 | F33: mechanism | G33: clipped-SGD trainStep | H33: One hand-derived step: gradient 2*(zPred - zTgt)/N clipped to [-1,1], backprop through Wp then Wc, returns the loss — plain readable autodiff by hand. | I33: obs_t, obs_t+1 | J33: updated Wc, Wp, scalar loss L | K33: learning-sanity ratio 0.34923 == run4 pin, re-bound bit-exact through round 10 | L33: postcondition | M33: P1_learning honestly FAILED on the easy world (ratio 0.948) in run 1 — kept as the verdict | N33: yes | O33: core/jepa.js:80-115
B34: quilt-jepa | C34: substrate | D34: quilt-jepa-P08 | E34: 1 | F34: mechanism | G34: deterministic corruption probe | H34: corruptWc flips the sign of a seeded fraction of Wc weights — the fault-injection lever for the zero-self-repair and cure-arm experiments. | I34: fraction, seed | J34: corrupted Wc, count flipped | K34: P6_zero_self_repair honestly FAILed in run 1 (jump_ratio 0.979) — the fault was permanent, receipted as design law paid for | L34: postcondition | N34: yes | O34: core/jepa.js:123-130; receipts/run.json verdicts
B35: quilt-jepa | C35: substrate | D35: quilt-jepa-P09 | E35: 0 | F35: substrate | G35: stride-4 mesh cells | H35: The mesh substrate: per-cell Float32 stride 4 [luminance, angle, gradient magnitude, latent/surprise energy], double-buffered with an active-side flag. | I35: obs, energy | J35: two n*4 buffers | K35: lambda = 0.2 <= 0.25 stability bound | L35: invariant | M35: lambda above 0.25 would make diffusion diverge | N35: yes | O35: core/mesh.js:1-17
B36: quilt-jepa | C36: substrate | D36: quilt-jepa-P10 | E36: 1 | F36: mechanism | G36: Perona-Malik diffusion step | H36: One pass on channel 3: each cell exchanges energy with 4 neighbors scaled by conductance exp(-((mc-nb)^2)/kappaSq) — flow pools in flat regions and stalls at edges. | I36: src buffer | J36: dst buffer (buffers swapped) | K36: total energy conserved to 1.2e-8 relative (P5 PASS; my scratch rerun measured 0.0 over 10 steps) | L36: conservation | M36: any asymmetry in the pairwise exchange would mint or destroy energy | N36: yes | O36: core/mesh.js:33-55
B37: quilt-jepa | C37: substrate | D37: quilt-jepa-P11 | E37: 1 | F37: mechanism | G37: variance contraction readout | H37: totals() folds the active buffer into {total, mean, variance}; the registered law requires variance non-increasing under diffusion. | I37: active buffer | J37: {total, mean, variance} | K37: p5_variance_non_increasing true (receipts/run.json) | L37: postcondition | N37: yes | O37: core/mesh.js:56-64
B38: quilt-jepa | C38: substrate | D38: quilt-jepa-P12 | E38: 2 | F38: policy | G38: surprise sampling policy | H38: surprise(sampleIdx) is mean |energy| over chosen cells — upgraded across rounds to percentile-z concentration statistics rather than global means (design law (b): diluted mean-surprise was the root cause of run-1's anomaly FAIL). | I38: energy channel, sample indices | J38: scalar surprise / z-concentration | K38: R3v4 z-conc 3.5407 > 3.0 (PASS, carried) | L38: postcondition | M38: global mean-surprise diluted the anomaly signal — the honest FAIL that forced law (b) | N38: yes | O38: core/mesh.js:65-70; README.md:26-28
B39: quilt-jepa | C39: substrate | D39: quilt-jepa-P13 | E39: 4 | F39: evidence | G39: registration seal (masked self-sha + mtime) | H39: Claims are sealed into registration.json BEFORE runs: the file hashes itself with its own sha field masked; the verifier recomputes and also binds the file mtime within 2s. | I39: registration.json bytes, stat mtime | J39: seal verdict | K39: masked self-sha recomputes exactly AND |mtime - sealed| <= 2000ms else fail-closed | L39: seal | M39: file mutated after seal -> 'FAIL registration self-sha mismatch (file mutated after seal)' | N39: yes | O39: verify.mjs:32-43
B40: quilt-jepa | C40: substrate | D40: quilt-jepa-P14 | E40: 4 | F40: evidence | G40: stone chain walk from GENESIS | H40: Every receipt row hashes as sha(prev : canonical{i,id,type,payload} : id); the verifier re-derives the whole chain from the JEPA-GENESIS-1 constant and demands the tip match. | I40: receipts/run.json | J40: chain verdict + tip | K40: every row re-hashes to its pin, links parent-correct, tip equal; exit 0 only if everything re-hashes | L40: postcondition | M40: 'FAIL hash mismatch at row N' names the tampered row | N40: yes | O40: verify.mjs:12-30
B41: quilt-jepa | C41: substrate | D41: quilt-jepa-P15 | E41: 2 | F41: policy | G41: fail-closed startup seal re-verification | H41: The run itself re-verifies the registration seal at startup and refuses to execute otherwise; the verdict is recorded in the receipt (seal_verified_at_startup). | I41: registration-v10.json at run time | J41: refusal or execution | K41: seal verified at startup, else the run refuses | L41: admission | M41: running against a mutated registration would decouple claims from measurements | N41: yes | O41: run10.mjs:24-26; verdict-v10.md:3-5
B42: quilt-jepa | C42: substrate | D42: quilt-jepa-P16 | E42: 4 | F42: evidence | G42: bit-exact cross-round re-binding | H42: Every round 4..9 metric must reproduce its round's receipt bit-exactly at sha level (run4 29/29, run5 92/92, design6/run6..run9 identities); the R4 twin executions are byte-identical (sha_round10_run1 == run2). | I42: carried receipts, fresh execution | J42: re-bound shas in the R4 row | K42: any sha mismatch fails the run — the operating point (lr 0.3, tau 0.99998, K4, amp, seed) is UNCHANGED or the round is void | L42: postcondition | M42: a core arithmetic change would break ten rounds of pinned shas | N42: yes | O42: run10.mjs:2-19; verdict-v10.md:26-28
...

Sheet Gates
B2: Gates the jevs swept (401 gates, rules pre-registered)
B4: work | C4: part_id | D4: layer | E4: layer_name | F4: gate_kind | G4: sweep_verdict | H4: gate
B5: qthe | C5: qthe-P01 | D5: 0 | E5: substrate | F5: postcondition | G5: OPEN | H5: 256/256 values round-trip exact AND 256 distinct packed outputs (gate G1)
B6: qthe | C6: qthe-P02 | D6: 0 | E6: substrate | F6: invariant | G6: OPEN | H6: PSI === [0, 1, -1, 'i'] asserted by G1
B7: qthe | C7: qthe-P03 | D7: 0 | E7: substrate | F7: postcondition | G7: OPEN | H7: hand-computed fixtures exact and every output Number.isInteger (G4: row0 [A10,R4,I6,G63] x xs[2,3,5,7] -> {re:8, im:30})
B8: qthe | C8: qthe-P04 | D8: 0 | E8: substrate | F8: precondition | G8: OPEN | H8: w, h positive integers else RangeError
B9: qthe | C9: qthe-P05 | D9: 1 | E9: mechanism | F9: invariant | G9: OPEN | H9: exactly SLOT_COUNT=64 slots; write outside [0,64) throws RangeError
B10: qthe | C10: qthe-P06 | D10: 1 | E10: mechanism | F10: postcondition | G10: OPEN | H10: lone Abstain cell never twins after its own first write; every event term === log2(3) exactly (G5 schedule)
B11: qthe | C11: qthe-P07 | D11: 1 | E11: mechanism | F11: postcondition | G11: OPEN | H11: totalWrites = 12 after the G5 6-tick twin fixture
B12: qthe | C12: qthe-P08 | D12: 2 | E12: policy | F12: budget | G12: OPEN | H12: the SPEC prices sigma as OPEN: only the sweep {log2(3), 0.5, 1, 2, 4} decides (C3); the gifted 'proof' is receipted as decorative
B13: qthe | C13: qthe-P09 | D13: 1 | E13: mechanism | F13: invariant | G13: OPEN | H13: tick mutates in place and returns the same substrate with synchronous-exact semantics
B14: qthe | C14: qthe-P10 | D14: 1 | E14: mechanism | F14: invariant | G14: OPEN | H14: G2 full-tick exhaustion: 3840/3840 cell-updates in bounds with tau preserved
B15: qthe | C15: qthe-P11 | D15: 1 | E15: mechanism | F15: postcondition | G15: OPEN | H15: 2304/2304 exhausted states x 9 pressures stay in [0,63] (G2a — the Coq theorem restated by exhaustion)
B16: qthe | C16: qthe-P12 | D16: 1 | E16: mechanism | F16: invariant | G16: OPEN | H16: G2: tau preserved EXACTLY on 3840/3840 updates
... B405: external-scouts | C405: external-scouts-P16 | D405: 2 | E405: policy | F405: precondition | G405: OPEN | H405: an unanchored pillar must carry pre-registered claims, not borrowed citations

Sheet Ideas
B2: Core ideas, decomposed (145 ideas)
B4: work | C4: idea_id | D4: name | E4: statement | F4: decomposed_into_parts
B5: qthe | C5: qthe-I1 | D5: The packed byte primitive (data is geometry, control is physics) | E5: A single byte splits into two planes: 6 bits of spatial amplitude d in [0,63] and 2 bits of timbre tau over {Ground, Attract, Repel, Abstain}, with the operator map Psi = [0, +1, -1, 'i'] and an exact split-channel vector pass — no floats anywhere in LAYER 0. | F5: qthe-P01, qthe-P02, qthe-P03, qthe-P04
B6: qthe | C6: qthe-I2 | D6: The 64-slot wormhole table as compile-time blueprint | E6: Abstain cells read/write a fixed 64-slot table: a twin hit on a different (x,y) with nonzero resonance injects resonance*sigma into the pressure (the imaginary channel entering through the only free degree of freedom), writes are last-writer-wins, and nobody resonates with their own write. | F6: qthe-P05, qthe-P06, qthe-P07, qthe-P08
B7: qthe | C7: qthe-I3 | D7: Deterministic Moore-8 tick with frozen timbre | E7: One synchronous, toroidal, double-buffered tick: neighbors read from the pre-tick snapshot, Attract/Repel accumulate signed d into pressure, data moves by a pure saturation rule toward 63 or 0, and tau never changes inside tick — same substrate plus same tick count is byte-identical, always. | F7: qthe-P09, qthe-P10, qthe-P11, qthe-P12, qthe-P13, qthe-P14, qthe-P16
B8: qthe | C8: qthe-I4 | D8: Pre-registered gates and stone receipts with honest failure | E8: Every gate's prediction is written before the run, observed numbers seal into a stone-v1 chain, a wrong prediction (G4's hand-arithmetic error) is kept forever by letter with the correction checked post-hoc, and an independent two-reader proves the chain fails closed at the tampered row. | F8: qthe-P17, qthe-P18, qthe-P19, qthe-P20
B9: quilt-jepa | C9: quilt-jepa-I1 | D9: The grid IS the latent space | E9: Each of the 16x16 cells holds its own 4-dim latent; a per-cell context encoder Wc and predictor Wp learn to predict the cell's own latent future against an EMA target encoder (tau, stop-gradient) — no pixel reconstruction anywhere. | F9: quilt-jepa-P03, quilt-jepa-P04, quilt-jepa-P05, quilt-jepa-P06, quilt-jepa-P07
B10: quilt-jepa | C10: quilt-jepa-I2 | D10: Conservation-law surprise mesh | E10: A double-buffered Perona-Malik anisotropic diffusion (lambda=0.2 <= 0.25 stability bound) moves prediction-surprise across the mesh as pairwise symmetric exchange: energy is never minted nor destroyed and variance contracts. | F10: quilt-jepa-P09, quilt-jepa-P10, quilt-jepa-P11, quilt-jepa-P12
B11: quilt-jepa | C11: quilt-jepa-I3 | D11: Determinism as the foundation of every claim | E11: The world is xorshift32-seeded with no Math.random, so twin runs are byte-identical; every experiment is registered and sealed BEFORE the run, the run re-verifies the seal at startup fail-closed, and a stone chain + verifier make tampering loud. | F11: quilt-jepa-P01, quilt-jepa-P13, quilt-jepa-P14, quilt-jepa-P15
B12: quilt-jepa | C12: quilt-jepa-I4 | D12: Bit-exact claim re-binding across the depth ladder | E12: Rounds 4..10 form a ladder where every carried metric must re-bind bit-exactly (run4 29/29, run5 92/92, cross-round metric shas) while only new claims are measured fresh — concentration statistics, not global means (design law (b)) — and honest FAILs (DOSE10, SAT10, DIP10) are carried as verdicts, not hidden. | F12: quilt-jepa-P16, quilt-jepa-P17, quilt-jepa-P18
B13: jev-quilt | C13: jev-quilt-I1 | D13: Identity never floats | E13: A cell is identified by integer quilt coordinates (k, s) plus declared type; values that are identities use the exact Q16 rational codec (num:int64, den:int64, always coprime) and floats are display-only projections — from_float refuses anything not representable rather than silently rounding. | F13: jev-quilt-P01, jev-quilt-P05, jev-quilt-P06
B14: jev-quilt | C14: jev-quilt-I2 | D14: Hooks eat deltas, not values | E14: A cell subscribes to a sibling's CHANGE (never a polled value): deltas below the hook's deadband floor are silent, a when-predicate can decline deltas whose shape isn't the hook's, and a broken predicate must never silence the fabric — every wake or silence is logged as a WakeResult. | F14: jev-quilt-P02, jev-quilt-P07, jev-quilt-P08, jev-quilt-P09, jev-quilt-P10
B15: jev-quilt | C15: jev-quilt-I3 | D15: Decide in one pass, project elsewhere; viability is binary | E15: The decider never renders and the renderer never decides (Law 3): a decision passes a binary confidence floor before it may project (Law 5); below the floor the outcome is booked as REJECTED, never projected, and a predictor pre-commits its feeling so the receipt binds feeling and fact in one hash. | F15: jev-quilt-P03, jev-quilt-P04, jev-quilt-P11, jev-quilt-P12
... B149: external-scouts | C149: external-scouts-I5 | D149: the dud channel and the novel part | E149: The continual-learning query returned pure junk (a Toyota production-system PPT, Philippine history, RuneScape gloves, SVN commit diffs) — the second failure of that channel on production-ML phrasing — receipted rather than deleted; consequently growth-from-usage has NO external anchor and is the part the garden builds novel, with pre-registered claims instead of citations. | F149: external-scouts-P15, external-scouts-P16, external-scouts-P17

Sheet Cells
B2: Each work re-rendered as quilt cells (366 cells)
B4: work | C4: cell_id | D4: kind | E4: expr | F4: deps | G4: maps_to_part
B5: qthe | C5: tau | D5: value | E5: c >> 6 (bit 7-6) | F5: byte | G5: qthe-P01
B6: qthe | C6: d | D6: value | E6: c & 0x3F (bit 5-0) | F6: byte | G6: qthe-P01
B7: qthe | C7: psi | D7: formula | E7: PSI[tau] = 0 | +1 | -1 | 'i' | F7: tau | G7: qthe-P02
B8: qthe | C8: vec_re | D8: formula | E8: sum(Attract d*x) - sum(Repel d*x) | F8: d, psi, x | G8: qthe-P03
B9: qthe | C9: vec_im | D9: formula | E9: sum(Abstain d*x) | F9: d, psi, x | G9: qthe-P03
B10: qthe | C10: acc | D10: formula | E10: Moore-8 signed sum of neighbor d (pre-tick snap) | F10: snap | G10: qthe-P10
B11: qthe | C11: twin | D11: listener | E11: slot[d] occupied by other (x,y) with r!=0 -> term = r*sigma | F11: d, wormholes | G11: qthe-P06
B12: qthe | C12: wh_write | D12: program | E12: slot[d] <- {x, y, |acc|+1}; last writer wins | F12: acc, d | G12: qthe-P07
B13: qthe | C13: sigma | D13: value | E13: log2(3) default, swept | G13: qthe-P08
B14: qthe | C14: next_d | D14: formula | E14: p>0 ? min(d+1,63) : p<0 ? max(d-1,0) : d | F14: acc, twin | G14: qthe-P11
B15: qthe | C15: byte_out | D15: formula | E15: (tau << 6) | next_d — tau frozen | F15: tau, next_d | G15: qthe-P12
B16: qthe | C16: trace | D16: formula | E16: traceView(cells) hash per tick | F16: byte_out, wormholes | G16: qthe-P15
B17: qthe | C17: rand_scan | D17: sensor | E17: count of Math.random in kernel === 0 | G17: qthe-P14
B18: qthe | C18: receipt | D18: io | E18: append {gate, pred, observed} to receipts.jsonl | F18: trace | G18: qthe-P18
B19: quilt-jepa | C19: obs | D19: value | E19: wave(x,y,t)*0.5+0.5 + ball bump (clipped) | F19: world.t | G19: quilt-jepa-P02
B20: quilt-jepa | C20: feat | D20: formula | E20: [l, r-l, d-l, l-0.5] per cell | F20: obs | G20: quilt-jepa-P03
B21: quilt-jepa | C21: z_ctx | D21: formula | E21: Wc[c] * feat | F21: feat | G21: quilt-jepa-P04
B22: quilt-jepa | C22: z_pred | D22: formula | E22: Wp[c] * z_ctx | F22: z_ctx | G22: quilt-jepa-P05
B23: quilt-jepa | C23: z_tgt | D23: formula | E23: Wt[c] * feat(t+1) | F23: feat, Wt | G23: quilt-jepa-P06
B24: quilt-jepa | C24: ema | D24: formula | E24: Wt <- 0.999*Wt + 0.001*Wc | F24: z_pred, z_tgt | G24: quilt-jepa-P06
B25: quilt-jepa | C25: loss | D25: formula | E25: mean((z_pred - z_tgt)^2), grads clipped [-1,1] | F25: z_pred, z_tgt | G25: quilt-jepa-P07
B26: quilt-jepa | C26: energy | D26: value | E26: channel-3 per mesh cell | F26: obs | G26: quilt-jepa-P09
B27: quilt-jepa | C27: flux | D27: formula | E27: sum_i lambda * exp(-((mc-ni)^2)/kappaSq) * (e_i - e) | F27: energy | G27: quilt-jepa-P10
B28: quilt-jepa | C28: totals | D28: sensor | E28: {total, variance} over active buffer; variance non-increasing | F28: flux | G28: quilt-jepa-P11
B29: quilt-jepa | C29: surprise_z | D29: formula | E29: percentile-z concentration over sampled cells | F29: totals | G29: quilt-jepa-P12
B30: quilt-jepa | C30: seal | D30: listener | E30: re-verify registration masked-sha + mtime at startup; refuse otherwise | G30: quilt-jepa-P13
B31: quilt-jepa | C31: chain | D31: io | E31: append receipt row; tip = sha(prev:body:id) | F31: loss, surprise_z | G31: quilt-jepa-P14
B32: quilt-jepa | C32: verdict | D32: sensor | E32: scorecard over claims; honest FAILs carried | F32: chain | G32: quilt-jepa-P17
B33: jev-quilt | C33: coord | D33: value | E33: (k, s) integers only — TypeError otherwise | G33: jev-quilt-P01
B34: jev-quilt | C34: q | D34: value | E34: Q16(num, den) coprime; from_float refuses unrepresentable | G34: jev-quilt-P05
B35: jev-quilt | C35: floor | D35: sensor | E35: |delta| >= hook.floor (Q16) else silent_deadband | F35: delta | G35: jev-quilt-P07
B36: jev-quilt | C36: when | D36: sensor | E36: hook.when(state); exception -> True (wake) | F36: state | G36: jev-quilt-P10
B37: jev-quilt | C37: backend | D37: router | E37: auto -> q16 -> openjev-local -> typesafe-api | F37: cell.backend | G37: jev-quilt-P13
B38: jev-quilt | C38: decision | D38: ai | E38: Choice | Score | Noul in one pass | F38: backend, state | G38: jev-quilt-P12
B39: jev-quilt | C39: viable | D39: sensor | E39: confidence > 0.0 (Law 5 binary floor) | F39: decision | G39: jev-quilt-P04
B40: jev-quilt | C40: project | D40: io | E40: Projection(to, as_type) only if viable; else booked REJECTED | F40: viable | G40: jev-quilt-P03
B41: jev-quilt | C41: book | D41: program | E41: append Receipt(tick, state_hash, delta_hash, kind, payload_hash) | F41: decision | G41: jev-quilt-P14
B42: jev-quilt | C42: sha | D42: formula | E42: fnv1a64 over UTF-8 of tick|state|delta|kind|payload_hash[|decision] | F42: book | G42: jev-quilt-P16
...

Sheet Ledger
B2: Timestamped ledgers (append-only; 106 rows)
B4: ts | C4: source | D4: lane | E4: work | F4: event | G4: detail
B5: 2026-10-04T06:59:27Z | C5: gatesweep-66-g.jsonl | D5: 66-g | E5: PRE-REGISTER | F5: rules | G5: {"R1_OPEN":"gate non-empty AND gate_kind non-null -> emit(g=0.75,e=0.25,d=0.50)","R2_SOFT":"gate non-empty AND gate_kind null -> emit(g=0.50,e=0.50,d=0.50)","R3_HOLE":"gate empty/null -> observe(d=0.20) explicit local collapse","R4_SEAL":"gate_kind in {seal,conservation} -> extra emit(g=0.85,e=0.15,d=0.50)","R5_LAYERHOLE":"work missing any layer 0..4 -> observe at that layer cell","R6_THIN":"work with <5 gated parts -> warning emit(g=0.35,e=0.65,d=0.50)","geometry":"work i -> q=(i%7)-3 ; layer L -> r=L-2 ; radius 6 ; policy ledger","backend":"atlas-sweep (deterministic structural judgment; no LLM, no network)"}
B6: 2026-10-04T06:59:27Z | C6: gatesweep-66-g.jsonl | D6: 66-g | E6: exoj | F6: swept | G6: parts=26 OPEN=24 SOFT=0 HOLE=2 seal2x=5 missingLayers=[] fm=24
B7: 2026-10-04T06:59:27Z | C7: gatesweep-66-g.jsonl | D7: 66-g | E7: fleet-seeds | F7: swept | G7: parts=16 OPEN=15 SOFT=0 HOLE=1 seal2x=3 missingLayers=[0] fm=16
B8: 2026-10-04T06:59:27Z | C8: gatesweep-66-g.jsonl | D8: 66-g | E8: jev-garden | F8: swept | G8: parts=26 OPEN=26 SOFT=0 HOLE=0 seal2x=2 missingLayers=[] fm=26
